[2024-06-20 12:27:23,292: INFO: data_ingestion: >>>>>> stage Data Ingestion stage started <<<<<<]
[2024-06-20 12:27:23,292: ERROR: data_ingestion: [Errno 2] No such file or directory: 'config/config.yaml']
Traceback (most recent call last):
  File "/Users/kaustubh/Documents/Kidney-Disease-Classification-using-DVC-and-MLflow/src/Classifier/pipeline/data_ingestion.py", line 25, in <module>
    obj.main()
  File "/Users/kaustubh/Documents/Kidney-Disease-Classification-using-DVC-and-MLflow/src/Classifier/pipeline/data_ingestion.py", line 13, in main
    config = ConfigurationManager()
             ^^^^^^^^^^^^^^^^^^^^^^
  File "/Users/kaustubh/Documents/Kidney-Disease-Classification-using-DVC-and-MLflow/src/Classifier/config/configuration.py", line 16, in __init__
    self.config = read_yaml(config_filepath)
                  ^^^^^^^^^^^^^^^^^^^^^^^^^^
  File "/Users/kaustubh/Documents/Kidney-Disease-Classification-using-DVC-and-MLflow/venv/lib/python3.12/site-packages/ensure/main.py", line 872, in __call__
    return_val = self.f(*args, **kwargs)
                 ^^^^^^^^^^^^^^^^^^^^^^^
  File "/Users/kaustubh/Documents/Kidney-Disease-Classification-using-DVC-and-MLflow/src/Classifier/utils/common.py", line 37, in read_yaml
    raise e
  File "/Users/kaustubh/Documents/Kidney-Disease-Classification-using-DVC-and-MLflow/src/Classifier/utils/common.py", line 30, in read_yaml
    with open(path_to_yaml) as yaml_file:
         ^^^^^^^^^^^^^^^^^^
FileNotFoundError: [Errno 2] No such file or directory: 'config/config.yaml'
[2024-06-20 12:33:08,303: INFO: data_ingestion: >>>>>> stage Data Ingestion stage started <<<<<<]
[2024-06-20 12:33:08,303: ERROR: data_ingestion: [Errno 2] No such file or directory: 'config/config.yaml']
Traceback (most recent call last):
  File "/Users/kaustubh/Documents/Kidney-Disease-Classification-using-DVC-and-MLflow/src/Classifier/pipeline/data_ingestion.py", line 25, in <module>
    obj.main()
  File "/Users/kaustubh/Documents/Kidney-Disease-Classification-using-DVC-and-MLflow/src/Classifier/pipeline/data_ingestion.py", line 13, in main
    config = ConfigurationManager()
             ^^^^^^^^^^^^^^^^^^^^^^
  File "/Users/kaustubh/Documents/Kidney-Disease-Classification-using-DVC-and-MLflow/src/Classifier/config/configuration.py", line 16, in __init__
    self.config = read_yaml(config_filepath)
                  ^^^^^^^^^^^^^^^^^^^^^^^^^^
  File "/Users/kaustubh/Documents/Kidney-Disease-Classification-using-DVC-and-MLflow/venv/lib/python3.12/site-packages/ensure/main.py", line 872, in __call__
    return_val = self.f(*args, **kwargs)
                 ^^^^^^^^^^^^^^^^^^^^^^^
  File "/Users/kaustubh/Documents/Kidney-Disease-Classification-using-DVC-and-MLflow/src/Classifier/utils/common.py", line 37, in read_yaml
    raise e
  File "/Users/kaustubh/Documents/Kidney-Disease-Classification-using-DVC-and-MLflow/src/Classifier/utils/common.py", line 30, in read_yaml
    with open(path_to_yaml) as yaml_file:
         ^^^^^^^^^^^^^^^^^^
FileNotFoundError: [Errno 2] No such file or directory: 'config/config.yaml'
[2024-06-20 12:35:03,502: INFO: data_ingestion: >>>>>> stage Data Ingestion stage started <<<<<<]
[2024-06-20 12:35:03,505: INFO: common: yaml file: /Users/kaustubh/Documents/Kidney-Disease-Classification-using-DVC-and-MLflow/config/config.yaml loaded successfully]
[2024-06-20 12:35:03,505: ERROR: data_ingestion: [Errno 2] No such file or directory: 'params.yaml']
Traceback (most recent call last):
  File "/Users/kaustubh/Documents/Kidney-Disease-Classification-using-DVC-and-MLflow/src/Classifier/pipeline/data_ingestion.py", line 25, in <module>
    obj.main()
  File "/Users/kaustubh/Documents/Kidney-Disease-Classification-using-DVC-and-MLflow/src/Classifier/pipeline/data_ingestion.py", line 13, in main
    config = ConfigurationManager()
             ^^^^^^^^^^^^^^^^^^^^^^
  File "/Users/kaustubh/Documents/Kidney-Disease-Classification-using-DVC-and-MLflow/src/Classifier/config/configuration.py", line 17, in __init__
    self.params = read_yaml(params_filepath)
                  ^^^^^^^^^^^^^^^^^^^^^^^^^^
  File "/Users/kaustubh/Documents/Kidney-Disease-Classification-using-DVC-and-MLflow/venv/lib/python3.12/site-packages/ensure/main.py", line 872, in __call__
    return_val = self.f(*args, **kwargs)
                 ^^^^^^^^^^^^^^^^^^^^^^^
  File "/Users/kaustubh/Documents/Kidney-Disease-Classification-using-DVC-and-MLflow/src/Classifier/utils/common.py", line 37, in read_yaml
    raise e
  File "/Users/kaustubh/Documents/Kidney-Disease-Classification-using-DVC-and-MLflow/src/Classifier/utils/common.py", line 30, in read_yaml
    with open(path_to_yaml) as yaml_file:
         ^^^^^^^^^^^^^^^^^^
FileNotFoundError: [Errno 2] No such file or directory: 'params.yaml'
[2024-06-20 12:35:35,152: INFO: data_ingestion: >>>>>> stage Data Ingestion stage started <<<<<<]
[2024-06-20 12:35:35,154: INFO: common: yaml file: /Users/kaustubh/Documents/Kidney-Disease-Classification-using-DVC-and-MLflow/config/config.yaml loaded successfully]
[2024-06-20 12:35:35,154: ERROR: data_ingestion: [Errno 2] No such file or directory: 'params.yaml']
Traceback (most recent call last):
  File "/Users/kaustubh/Documents/Kidney-Disease-Classification-using-DVC-and-MLflow/src/Classifier/pipeline/data_ingestion.py", line 25, in <module>
    obj.main()
  File "/Users/kaustubh/Documents/Kidney-Disease-Classification-using-DVC-and-MLflow/src/Classifier/pipeline/data_ingestion.py", line 13, in main
    config = ConfigurationManager()
             ^^^^^^^^^^^^^^^^^^^^^^
  File "/Users/kaustubh/Documents/Kidney-Disease-Classification-using-DVC-and-MLflow/src/Classifier/config/configuration.py", line 17, in __init__
    self.params = read_yaml(params_filepath)
                  ^^^^^^^^^^^^^^^^^^^^^^^^^^
  File "/Users/kaustubh/Documents/Kidney-Disease-Classification-using-DVC-and-MLflow/venv/lib/python3.12/site-packages/ensure/main.py", line 872, in __call__
    return_val = self.f(*args, **kwargs)
                 ^^^^^^^^^^^^^^^^^^^^^^^
  File "/Users/kaustubh/Documents/Kidney-Disease-Classification-using-DVC-and-MLflow/src/Classifier/utils/common.py", line 37, in read_yaml
    raise e
  File "/Users/kaustubh/Documents/Kidney-Disease-Classification-using-DVC-and-MLflow/src/Classifier/utils/common.py", line 30, in read_yaml
    with open(path_to_yaml) as yaml_file:
         ^^^^^^^^^^^^^^^^^^
FileNotFoundError: [Errno 2] No such file or directory: 'params.yaml'
[2024-06-20 12:36:03,677: INFO: data_ingestion: >>>>>> stage Data Ingestion stage started <<<<<<]
[2024-06-20 12:36:03,678: INFO: common: yaml file: /Users/kaustubh/Documents/Kidney-Disease-Classification-using-DVC-and-MLflow/config/config.yaml loaded successfully]
[2024-06-20 12:36:03,680: INFO: common: yaml file: /Users/kaustubh/Documents/Kidney-Disease-Classification-using-DVC-and-MLflow/params.yaml loaded successfully]
[2024-06-20 12:36:03,680: INFO: common: created directory at: artifacts]
[2024-06-20 12:36:03,680: INFO: common: created directory at: artifacts/data_ingestion]
[2024-06-20 12:36:03,680: INFO: data_ingestion: Downloading data from https://drive.google.com/file/d/1vlhZ5c7abUKF8xXERIw6m9Te8fW7ohw3/view?usp=sharing into file artifacts/data_ingestion/data.zip]
[2024-06-20 12:36:06,493: INFO: data_ingestion: Downloaded data from https://drive.google.com/file/d/1vlhZ5c7abUKF8xXERIw6m9Te8fW7ohw3/view?usp=sharing into file artifacts/data_ingestion/data.zip]
[2024-06-20 12:36:06,925: INFO: data_ingestion: >>>>>> stage Data Ingestion stage completed <<<<<<

x==========x]
[2024-06-20 12:52:03,493: INFO: prepare_base_model: *******************]
[2024-06-20 12:52:03,494: INFO: prepare_base_model: >>>>>> stage Prepare base model started <<<<<<]
[2024-06-20 12:52:03,497: INFO: common: yaml file: /Users/kaustubh/Documents/Kidney-Disease-Classification-using-DVC-and-MLflow/config/config.yaml loaded successfully]
[2024-06-20 12:52:03,499: INFO: common: yaml file: /Users/kaustubh/Documents/Kidney-Disease-Classification-using-DVC-and-MLflow/params.yaml loaded successfully]
[2024-06-20 12:52:03,499: INFO: common: created directory at: artifacts]
[2024-06-20 12:52:03,500: INFO: common: created directory at: artifacts/prepare_base_model]
[2024-06-20 12:52:03,928: ERROR: prepare_base_model: URL fetch failure on https://storage.googleapis.com/tensorflow/keras-applications/vgg16/vgg16_weights_tf_dim_ordering_tf_kernels_notop.h5: None -- [SSL: CERTIFICATE_VERIFY_FAILED] certificate verify failed: unable to get local issuer certificate (_ssl.c:1000)]
Traceback (most recent call last):
  File "/Library/Frameworks/Python.framework/Versions/3.12/lib/python3.12/urllib/request.py", line 1344, in do_open
    h.request(req.get_method(), req.selector, req.data, headers,
  File "/Library/Frameworks/Python.framework/Versions/3.12/lib/python3.12/http/client.py", line 1336, in request
    self._send_request(method, url, body, headers, encode_chunked)
  File "/Library/Frameworks/Python.framework/Versions/3.12/lib/python3.12/http/client.py", line 1382, in _send_request
    self.endheaders(body, encode_chunked=encode_chunked)
  File "/Library/Frameworks/Python.framework/Versions/3.12/lib/python3.12/http/client.py", line 1331, in endheaders
    self._send_output(message_body, encode_chunked=encode_chunked)
  File "/Library/Frameworks/Python.framework/Versions/3.12/lib/python3.12/http/client.py", line 1091, in _send_output
    self.send(msg)
  File "/Library/Frameworks/Python.framework/Versions/3.12/lib/python3.12/http/client.py", line 1035, in send
    self.connect()
  File "/Library/Frameworks/Python.framework/Versions/3.12/lib/python3.12/http/client.py", line 1477, in connect
    self.sock = self._context.wrap_socket(self.sock,
                ^^^^^^^^^^^^^^^^^^^^^^^^^^^^^^^^^^^^
  File "/Library/Frameworks/Python.framework/Versions/3.12/lib/python3.12/ssl.py", line 455, in wrap_socket
    return self.sslsocket_class._create(
           ^^^^^^^^^^^^^^^^^^^^^^^^^^^^^
  File "/Library/Frameworks/Python.framework/Versions/3.12/lib/python3.12/ssl.py", line 1042, in _create
    self.do_handshake()
  File "/Library/Frameworks/Python.framework/Versions/3.12/lib/python3.12/ssl.py", line 1320, in do_handshake
    self._sslobj.do_handshake()
ssl.SSLCertVerificationError: [SSL: CERTIFICATE_VERIFY_FAILED] certificate verify failed: unable to get local issuer certificate (_ssl.c:1000)

During handling of the above exception, another exception occurred:

Traceback (most recent call last):
  File "/Users/kaustubh/Documents/Kidney-Disease-Classification-using-DVC-and-MLflow/venv/lib/python3.12/site-packages/keras/src/utils/file_utils.py", line 291, in get_file
    urlretrieve(origin, fpath, DLProgbar())
  File "/Library/Frameworks/Python.framework/Versions/3.12/lib/python3.12/urllib/request.py", line 240, in urlretrieve
    with contextlib.closing(urlopen(url, data)) as fp:
                            ^^^^^^^^^^^^^^^^^^
  File "/Library/Frameworks/Python.framework/Versions/3.12/lib/python3.12/urllib/request.py", line 215, in urlopen
    return opener.open(url, data, timeout)
           ^^^^^^^^^^^^^^^^^^^^^^^^^^^^^^^
  File "/Library/Frameworks/Python.framework/Versions/3.12/lib/python3.12/urllib/request.py", line 515, in open
    response = self._open(req, data)
               ^^^^^^^^^^^^^^^^^^^^^
  File "/Library/Frameworks/Python.framework/Versions/3.12/lib/python3.12/urllib/request.py", line 532, in _open
    result = self._call_chain(self.handle_open, protocol, protocol +
             ^^^^^^^^^^^^^^^^^^^^^^^^^^^^^^^^^^^^^^^^^^^^^^^^^^^^^^^
  File "/Library/Frameworks/Python.framework/Versions/3.12/lib/python3.12/urllib/request.py", line 492, in _call_chain
    result = func(*args)
             ^^^^^^^^^^^
  File "/Library/Frameworks/Python.framework/Versions/3.12/lib/python3.12/urllib/request.py", line 1392, in https_open
    return self.do_open(http.client.HTTPSConnection, req,
           ^^^^^^^^^^^^^^^^^^^^^^^^^^^^^^^^^^^^^^^^^^^^^^
  File "/Library/Frameworks/Python.framework/Versions/3.12/lib/python3.12/urllib/request.py", line 1347, in do_open
    raise URLError(err)
urllib.error.URLError: <urlopen error [SSL: CERTIFICATE_VERIFY_FAILED] certificate verify failed: unable to get local issuer certificate (_ssl.c:1000)>

During handling of the above exception, another exception occurred:

Traceback (most recent call last):
  File "/Users/kaustubh/Documents/Kidney-Disease-Classification-using-DVC-and-MLflow/src/Classifier/pipeline/prepare_base_model.py", line 27, in <module>
    obj.main()
  File "/Users/kaustubh/Documents/Kidney-Disease-Classification-using-DVC-and-MLflow/src/Classifier/pipeline/prepare_base_model.py", line 17, in main
    prepare_base_model.get_base_model()
  File "/Users/kaustubh/Documents/Kidney-Disease-Classification-using-DVC-and-MLflow/src/Classifier/components/prepare_base_model.py", line 15, in get_base_model
    self.model = tf.keras.applications.vgg16.VGG16(
                 ^^^^^^^^^^^^^^^^^^^^^^^^^^^^^^^^^^
  File "/Users/kaustubh/Documents/Kidney-Disease-Classification-using-DVC-and-MLflow/venv/lib/python3.12/site-packages/keras/src/applications/vgg16.py", line 216, in VGG16
    weights_path = file_utils.get_file(
                   ^^^^^^^^^^^^^^^^^^^^
  File "/Users/kaustubh/Documents/Kidney-Disease-Classification-using-DVC-and-MLflow/venv/lib/python3.12/site-packages/keras/src/utils/file_utils.py", line 295, in get_file
    raise Exception(error_msg.format(origin, e.errno, e.reason))
Exception: URL fetch failure on https://storage.googleapis.com/tensorflow/keras-applications/vgg16/vgg16_weights_tf_dim_ordering_tf_kernels_notop.h5: None -- [SSL: CERTIFICATE_VERIFY_FAILED] certificate verify failed: unable to get local issuer certificate (_ssl.c:1000)
[2024-06-20 12:56:04,212: INFO: prepare_base_model: *******************]
[2024-06-20 12:56:04,213: INFO: prepare_base_model: >>>>>> stage Prepare base model started <<<<<<]
[2024-06-20 12:56:04,215: INFO: common: yaml file: /Users/kaustubh/Documents/Kidney-Disease-Classification-using-DVC-and-MLflow/config/config.yaml loaded successfully]
[2024-06-20 12:56:04,217: INFO: common: yaml file: /Users/kaustubh/Documents/Kidney-Disease-Classification-using-DVC-and-MLflow/params.yaml loaded successfully]
[2024-06-20 12:56:04,218: INFO: common: created directory at: artifacts]
[2024-06-20 12:56:04,218: INFO: common: created directory at: artifacts/prepare_base_model]
[2024-06-20 12:56:04,590: ERROR: prepare_base_model: URL fetch failure on https://storage.googleapis.com/tensorflow/keras-applications/vgg16/vgg16_weights_tf_dim_ordering_tf_kernels_notop.h5: None -- [SSL: CERTIFICATE_VERIFY_FAILED] certificate verify failed: unable to get local issuer certificate (_ssl.c:1000)]
Traceback (most recent call last):
  File "/Library/Frameworks/Python.framework/Versions/3.12/lib/python3.12/urllib/request.py", line 1344, in do_open
    h.request(req.get_method(), req.selector, req.data, headers,
  File "/Library/Frameworks/Python.framework/Versions/3.12/lib/python3.12/http/client.py", line 1336, in request
    self._send_request(method, url, body, headers, encode_chunked)
  File "/Library/Frameworks/Python.framework/Versions/3.12/lib/python3.12/http/client.py", line 1382, in _send_request
    self.endheaders(body, encode_chunked=encode_chunked)
  File "/Library/Frameworks/Python.framework/Versions/3.12/lib/python3.12/http/client.py", line 1331, in endheaders
    self._send_output(message_body, encode_chunked=encode_chunked)
  File "/Library/Frameworks/Python.framework/Versions/3.12/lib/python3.12/http/client.py", line 1091, in _send_output
    self.send(msg)
  File "/Library/Frameworks/Python.framework/Versions/3.12/lib/python3.12/http/client.py", line 1035, in send
    self.connect()
  File "/Library/Frameworks/Python.framework/Versions/3.12/lib/python3.12/http/client.py", line 1477, in connect
    self.sock = self._context.wrap_socket(self.sock,
                ^^^^^^^^^^^^^^^^^^^^^^^^^^^^^^^^^^^^
  File "/Library/Frameworks/Python.framework/Versions/3.12/lib/python3.12/ssl.py", line 455, in wrap_socket
    return self.sslsocket_class._create(
           ^^^^^^^^^^^^^^^^^^^^^^^^^^^^^
  File "/Library/Frameworks/Python.framework/Versions/3.12/lib/python3.12/ssl.py", line 1042, in _create
    self.do_handshake()
  File "/Library/Frameworks/Python.framework/Versions/3.12/lib/python3.12/ssl.py", line 1320, in do_handshake
    self._sslobj.do_handshake()
ssl.SSLCertVerificationError: [SSL: CERTIFICATE_VERIFY_FAILED] certificate verify failed: unable to get local issuer certificate (_ssl.c:1000)

During handling of the above exception, another exception occurred:

Traceback (most recent call last):
  File "/Users/kaustubh/Documents/Kidney-Disease-Classification-using-DVC-and-MLflow/venv/lib/python3.12/site-packages/keras/src/utils/file_utils.py", line 291, in get_file
    urlretrieve(origin, fpath, DLProgbar())
  File "/Library/Frameworks/Python.framework/Versions/3.12/lib/python3.12/urllib/request.py", line 240, in urlretrieve
    with contextlib.closing(urlopen(url, data)) as fp:
                            ^^^^^^^^^^^^^^^^^^
  File "/Library/Frameworks/Python.framework/Versions/3.12/lib/python3.12/urllib/request.py", line 215, in urlopen
    return opener.open(url, data, timeout)
           ^^^^^^^^^^^^^^^^^^^^^^^^^^^^^^^
  File "/Library/Frameworks/Python.framework/Versions/3.12/lib/python3.12/urllib/request.py", line 515, in open
    response = self._open(req, data)
               ^^^^^^^^^^^^^^^^^^^^^
  File "/Library/Frameworks/Python.framework/Versions/3.12/lib/python3.12/urllib/request.py", line 532, in _open
    result = self._call_chain(self.handle_open, protocol, protocol +
             ^^^^^^^^^^^^^^^^^^^^^^^^^^^^^^^^^^^^^^^^^^^^^^^^^^^^^^^
  File "/Library/Frameworks/Python.framework/Versions/3.12/lib/python3.12/urllib/request.py", line 492, in _call_chain
    result = func(*args)
             ^^^^^^^^^^^
  File "/Library/Frameworks/Python.framework/Versions/3.12/lib/python3.12/urllib/request.py", line 1392, in https_open
    return self.do_open(http.client.HTTPSConnection, req,
           ^^^^^^^^^^^^^^^^^^^^^^^^^^^^^^^^^^^^^^^^^^^^^^
  File "/Library/Frameworks/Python.framework/Versions/3.12/lib/python3.12/urllib/request.py", line 1347, in do_open
    raise URLError(err)
urllib.error.URLError: <urlopen error [SSL: CERTIFICATE_VERIFY_FAILED] certificate verify failed: unable to get local issuer certificate (_ssl.c:1000)>

During handling of the above exception, another exception occurred:

Traceback (most recent call last):
  File "/Users/kaustubh/Documents/Kidney-Disease-Classification-using-DVC-and-MLflow/src/Classifier/pipeline/prepare_base_model.py", line 27, in <module>
    obj.main()
  File "/Users/kaustubh/Documents/Kidney-Disease-Classification-using-DVC-and-MLflow/src/Classifier/pipeline/prepare_base_model.py", line 17, in main
    prepare_base_model.get_base_model()
  File "/Users/kaustubh/Documents/Kidney-Disease-Classification-using-DVC-and-MLflow/src/Classifier/components/prepare_base_model.py", line 15, in get_base_model
    self.model = tf.keras.applications.vgg16.VGG16(
                 ^^^^^^^^^^^^^^^^^^^^^^^^^^^^^^^^^^
  File "/Users/kaustubh/Documents/Kidney-Disease-Classification-using-DVC-and-MLflow/venv/lib/python3.12/site-packages/keras/src/applications/vgg16.py", line 216, in VGG16
    weights_path = file_utils.get_file(
                   ^^^^^^^^^^^^^^^^^^^^
  File "/Users/kaustubh/Documents/Kidney-Disease-Classification-using-DVC-and-MLflow/venv/lib/python3.12/site-packages/keras/src/utils/file_utils.py", line 295, in get_file
    raise Exception(error_msg.format(origin, e.errno, e.reason))
Exception: URL fetch failure on https://storage.googleapis.com/tensorflow/keras-applications/vgg16/vgg16_weights_tf_dim_ordering_tf_kernels_notop.h5: None -- [SSL: CERTIFICATE_VERIFY_FAILED] certificate verify failed: unable to get local issuer certificate (_ssl.c:1000)
[2024-06-20 13:01:45,635: INFO: prepare_base_model: *******************]
[2024-06-20 13:01:45,635: INFO: prepare_base_model: >>>>>> stage Prepare base model started <<<<<<]
[2024-06-20 13:01:45,637: INFO: common: yaml file: /Users/kaustubh/Documents/Kidney-Disease-Classification-using-DVC-and-MLflow/config/config.yaml loaded successfully]
[2024-06-20 13:01:45,638: INFO: common: yaml file: /Users/kaustubh/Documents/Kidney-Disease-Classification-using-DVC-and-MLflow/params.yaml loaded successfully]
[2024-06-20 13:01:45,638: INFO: common: created directory at: artifacts]
[2024-06-20 13:01:45,638: INFO: common: created directory at: artifacts/prepare_base_model]
[2024-06-20 13:01:45,895: ERROR: prepare_base_model: URL fetch failure on https://storage.googleapis.com/tensorflow/keras-applications/vgg16/vgg16_weights_tf_dim_ordering_tf_kernels_notop.h5: None -- [SSL: CERTIFICATE_VERIFY_FAILED] certificate verify failed: unable to get local issuer certificate (_ssl.c:1000)]
Traceback (most recent call last):
  File "/Library/Frameworks/Python.framework/Versions/3.12/lib/python3.12/urllib/request.py", line 1344, in do_open
    h.request(req.get_method(), req.selector, req.data, headers,
  File "/Library/Frameworks/Python.framework/Versions/3.12/lib/python3.12/http/client.py", line 1336, in request
    self._send_request(method, url, body, headers, encode_chunked)
  File "/Library/Frameworks/Python.framework/Versions/3.12/lib/python3.12/http/client.py", line 1382, in _send_request
    self.endheaders(body, encode_chunked=encode_chunked)
  File "/Library/Frameworks/Python.framework/Versions/3.12/lib/python3.12/http/client.py", line 1331, in endheaders
    self._send_output(message_body, encode_chunked=encode_chunked)
  File "/Library/Frameworks/Python.framework/Versions/3.12/lib/python3.12/http/client.py", line 1091, in _send_output
    self.send(msg)
  File "/Library/Frameworks/Python.framework/Versions/3.12/lib/python3.12/http/client.py", line 1035, in send
    self.connect()
  File "/Library/Frameworks/Python.framework/Versions/3.12/lib/python3.12/http/client.py", line 1477, in connect
    self.sock = self._context.wrap_socket(self.sock,
                ^^^^^^^^^^^^^^^^^^^^^^^^^^^^^^^^^^^^
  File "/Library/Frameworks/Python.framework/Versions/3.12/lib/python3.12/ssl.py", line 455, in wrap_socket
    return self.sslsocket_class._create(
           ^^^^^^^^^^^^^^^^^^^^^^^^^^^^^
  File "/Library/Frameworks/Python.framework/Versions/3.12/lib/python3.12/ssl.py", line 1042, in _create
    self.do_handshake()
  File "/Library/Frameworks/Python.framework/Versions/3.12/lib/python3.12/ssl.py", line 1320, in do_handshake
    self._sslobj.do_handshake()
ssl.SSLCertVerificationError: [SSL: CERTIFICATE_VERIFY_FAILED] certificate verify failed: unable to get local issuer certificate (_ssl.c:1000)

During handling of the above exception, another exception occurred:

Traceback (most recent call last):
  File "/Users/kaustubh/Documents/Kidney-Disease-Classification-using-DVC-and-MLflow/venv/lib/python3.12/site-packages/keras/src/utils/file_utils.py", line 291, in get_file
    urlretrieve(origin, fpath, DLProgbar())
  File "/Library/Frameworks/Python.framework/Versions/3.12/lib/python3.12/urllib/request.py", line 240, in urlretrieve
    with contextlib.closing(urlopen(url, data)) as fp:
                            ^^^^^^^^^^^^^^^^^^
  File "/Library/Frameworks/Python.framework/Versions/3.12/lib/python3.12/urllib/request.py", line 215, in urlopen
    return opener.open(url, data, timeout)
           ^^^^^^^^^^^^^^^^^^^^^^^^^^^^^^^
  File "/Library/Frameworks/Python.framework/Versions/3.12/lib/python3.12/urllib/request.py", line 515, in open
    response = self._open(req, data)
               ^^^^^^^^^^^^^^^^^^^^^
  File "/Library/Frameworks/Python.framework/Versions/3.12/lib/python3.12/urllib/request.py", line 532, in _open
    result = self._call_chain(self.handle_open, protocol, protocol +
             ^^^^^^^^^^^^^^^^^^^^^^^^^^^^^^^^^^^^^^^^^^^^^^^^^^^^^^^
  File "/Library/Frameworks/Python.framework/Versions/3.12/lib/python3.12/urllib/request.py", line 492, in _call_chain
    result = func(*args)
             ^^^^^^^^^^^
  File "/Library/Frameworks/Python.framework/Versions/3.12/lib/python3.12/urllib/request.py", line 1392, in https_open
    return self.do_open(http.client.HTTPSConnection, req,
           ^^^^^^^^^^^^^^^^^^^^^^^^^^^^^^^^^^^^^^^^^^^^^^
  File "/Library/Frameworks/Python.framework/Versions/3.12/lib/python3.12/urllib/request.py", line 1347, in do_open
    raise URLError(err)
urllib.error.URLError: <urlopen error [SSL: CERTIFICATE_VERIFY_FAILED] certificate verify failed: unable to get local issuer certificate (_ssl.c:1000)>

During handling of the above exception, another exception occurred:

Traceback (most recent call last):
  File "/Users/kaustubh/Documents/Kidney-Disease-Classification-using-DVC-and-MLflow/src/Classifier/pipeline/prepare_base_model.py", line 27, in <module>
    obj.main()
  File "/Users/kaustubh/Documents/Kidney-Disease-Classification-using-DVC-and-MLflow/src/Classifier/pipeline/prepare_base_model.py", line 17, in main
    prepare_base_model.get_base_model()
  File "/Users/kaustubh/Documents/Kidney-Disease-Classification-using-DVC-and-MLflow/src/Classifier/components/prepare_base_model.py", line 15, in get_base_model
    self.model = tf.keras.applications.vgg16.VGG16(
                 ^^^^^^^^^^^^^^^^^^^^^^^^^^^^^^^^^^
  File "/Users/kaustubh/Documents/Kidney-Disease-Classification-using-DVC-and-MLflow/venv/lib/python3.12/site-packages/keras/src/applications/vgg16.py", line 216, in VGG16
    weights_path = file_utils.get_file(
                   ^^^^^^^^^^^^^^^^^^^^
  File "/Users/kaustubh/Documents/Kidney-Disease-Classification-using-DVC-and-MLflow/venv/lib/python3.12/site-packages/keras/src/utils/file_utils.py", line 295, in get_file
    raise Exception(error_msg.format(origin, e.errno, e.reason))
Exception: URL fetch failure on https://storage.googleapis.com/tensorflow/keras-applications/vgg16/vgg16_weights_tf_dim_ordering_tf_kernels_notop.h5: None -- [SSL: CERTIFICATE_VERIFY_FAILED] certificate verify failed: unable to get local issuer certificate (_ssl.c:1000)
[2024-06-20 13:04:01,400: INFO: prepare_base_model: *******************]
[2024-06-20 13:04:01,401: INFO: prepare_base_model: >>>>>> stage Prepare base model started <<<<<<]
[2024-06-20 13:04:01,405: INFO: common: yaml file: /Users/kaustubh/Documents/Kidney-Disease-Classification-using-DVC-and-MLflow/config/config.yaml loaded successfully]
[2024-06-20 13:04:01,407: INFO: common: yaml file: /Users/kaustubh/Documents/Kidney-Disease-Classification-using-DVC-and-MLflow/params.yaml loaded successfully]
[2024-06-20 13:04:01,408: INFO: common: created directory at: artifacts]
[2024-06-20 13:04:01,408: INFO: common: created directory at: artifacts/prepare_base_model]
[2024-06-20 13:04:03,560: WARNING: saving_api: You are saving your model as an HDF5 file via `model.save()` or `keras.saving.save_model(model)`. This file format is considered legacy. We recommend using instead the native Keras format, e.g. `model.save('my_model.keras')` or `keras.saving.save_model(model, 'my_model.keras')`. ]
[2024-06-20 13:04:03,676: WARNING: saving_api: You are saving your model as an HDF5 file via `model.save()` or `keras.saving.save_model(model)`. This file format is considered legacy. We recommend using instead the native Keras format, e.g. `model.save('my_model.keras')` or `keras.saving.save_model(model, 'my_model.keras')`. ]
[2024-06-20 13:04:03,741: INFO: prepare_base_model: >>>>>> stage Prepare base model completed <<<<<<

x==========x]
